Workbook

Sheet Assumptions
A1: Meera for Creators — Credit Sheet: Assumptions
A2: Every number below is editable. Every other sheet computes off these cells — nothing downstream is a pasted number.
A3: FX
A4: USD to INR | B4: 84 | C4: Per instruction, used for every INR conversion on this sheet. Note: influora-ai/app/costs/pricing.py bakes Rs.83/$1 as its own internal SARVAM_USD_PER_INR constant for the TTS $ rate (row 19) — that is a separate, code-level fact reproduced as-is; it is NOT swapped for 84, only the resulting USD amount is converted to INR at 84 like everything else.
A6: Anthropic model pricing — source: influora-ai/app/costs/pricing.py PRICING_TABLE (verified 2026-07-11/12)
A7: Sonnet model id (CLAUDE_MODEL default, used for the live creator chat turn) | B7: claude-sonnet-4-5-20250929
A8: Sonnet input $ / MTok | B8: 3
A9: Sonnet output $ / MTok | B9: 15
A10: Sonnet cache READ multiplier (x input rate) | B10: 0.1
A11: Sonnet cache WRITE multiplier (x input rate) | B11: 1.25
A12: Haiku model id (TRENDSPARK_MODEL; BRIEF_EXTRACT_MODEL defaults to this per SPEC.md 7.5) | B12: claude-haiku-4-5-20251001
A13: Haiku input $ / MTok | B13: 1
A14: Haiku output $ / MTok | B14: 5
A16: Sarvam voice pricing — source: pricing.py
A17: STT flat $ / call (SARVAM_FLAT_COST_PER_CALL) | B17: 0.006
A18: TTS INR per 10,000 chars (SARVAM_TTS_INR_PER_10K_CHARS) | B18: 30
A19: TTS internal USD/INR constant used inside pricing.py (SARVAM_USD_PER_INR = 1/83) | B19: =1/83
A20: TTS USD per 10,000 chars (derived — matches pricing.py SARVAM_TTS_USD_PER_10K_CHARS) | B20: =B18*B19
A22: Chat turn assumptions (Sonnet, one creator chat turn)
A23: Input tokens per turn | B23: 2500
A24: Cacheable fraction of input tokens (Block A/B prefix) | B24: 0.9
A25: Output tokens per turn | B25: 200
A26: Cache hit rate on Block A/B (baseline) | B26: 0.7
A27: Probability a turn includes one tool-call round trip | B27: 0.4
A28: Extra input tokens on a tool round trip (uncached tool_result) | B28: 300
A29: Extra output tokens on a tool round trip (final reply after tool use) | B29: 100
A31: Brief extraction assumptions (Haiku — SPEC.md §7.5, BRIEF_EXTRACT_MODEL)
A32: Input tokens per extraction | B32: 1500
A33: Output tokens per extraction | B33: 400
A35: Voice turn assumptions
A36: TTS characters per voice turn | B36: 300
A37: Voice turns are ADDITIVE on top of one of the persona's chat turns (Sarvam STT+TTS layered onto a turn that already happened), not separate chat completions — matches the "voice is additive" design note in influora-ai/app/config.py.
A39: Weekly digest assumptions (Haiku — sized to the same order of magnitude as brief extraction; not yet built)
A40: Input tokens per digest | B40: 1200
A41: Output tokens per digest | B41: 300
A42: Digests per month (52 weeks / 12 months) | B42: =52/12
A44: Platform + deal economics
A45: Platform fee percent (application.yml PLATFORM_FEE_PERCENT default) | B45: 0.15
A46: Typical deal size (INR) | B46: 5000
A48: Per-creator AI spend cap — source: influora-ai/app/config.py ai_creator_monthly_cap_usd
...

Sheet UnitCosts
A1: Unit Cost Model
A3: Effective per-token rates ($/token)
A4: Model | B4: Input | C4: Output | D4: Cache read | E4: Cache write
A5: Sonnet | B5: =Assumptions!B8/1000000 | C5: =Assumptions!B9/1000000 | D5: =B5*Assumptions!B10 | E5: =B5*Assumptions!B11
A6: Haiku | B6: =Assumptions!B13/1000000 | C6: =Assumptions!B14/1000000
A8: Cost per creator chat turn (Sonnet)
A9: Cacheable input tokens | B9: =Assumptions!B23*Assumptions!B24
A10: Fresh (uncached) input tokens | B10: =Assumptions!B23*(1-Assumptions!B24)
A11: Blended cache rate $/token (hit-rate weighted) | B11: =Assumptions!B26*D5+(1-Assumptions!B26)*E5
A12: Cacheable-tokens cost $ | B12: =B9*B11
A13: Fresh-input cost $ | B13: =B10*B5
A14: Output cost $ | B14: =Assumptions!B25*C5
A15: Base turn cost $ (no tool call) | B15: =B12+B13+B14
A16: Tool round-trip extra cost $ (if it happens) | B16: =Assumptions!B28*B5+Assumptions!B29*C5
A17: Expected tool-call cost $ (probability-weighted) | B17: =Assumptions!B27*B16
A18: Cost per chat turn $ (expected) | B18: =B15+B17
A19: Cost per chat turn, INR | B19: =B18*Assumptions!B4
A21: Cost per brief extraction (Haiku)
A22: Cost $ | B22: =Assumptions!B32*B6+Assumptions!B33*C6
A23: Cost, INR | B23: =B22*Assumptions!B4
A25: Cost per voice turn (Sarvam STT + TTS; additive over one chat turn — see Assumptions row 37)
A26: STT $ (flat) | B26: =Assumptions!B17
A27: TTS $ (char-scaled) | B27: =(Assumptions!B36/10000)*Assumptions!B20
A28: Total voice overhead $ | B28: =B26+B27
A29: Total voice overhead, INR | B29: =B28*Assumptions!B4
A31: Cost per weekly digest (Haiku)
A32: Cost $ | B32: =Assumptions!B40*B6+Assumptions!B41*C6
A33: Cost, INR | B33: =B32*Assumptions!B4

Sheet Personas
A1: Usage Personas — Monthly AI Cost per Creator
A3: Persona | B3: Turns | C3: Briefs | D3: Voice | E3: Monthly cost $ | F3: Monthly cost INR | G3: Credits used (Option B/C def.)
A4: Light | B4: =Assumptions!B57 | C4: =Assumptions!C57 | D4: =Assumptions!D57 | E4: =B4*UnitCosts!$B$18+C4*UnitCosts!$B$22+D4*UnitCosts!$B$28+Assumptions!$B$42*UnitCosts!$B$32 | F4: =E4*Assumptions!$B$4 | G4: =B4*Assumptions!$B$63+C4*Assumptions!$B$64+D4*Assumptions!$B$65
A5: Typical | B5: =Assumptions!B58 | C5: =Assumptions!C58 | D5: =Assumptions!D58 | E5: =B5*UnitCosts!$B$18+C5*UnitCosts!$B$22+D5*UnitCosts!$B$28+Assumptions!$B$42*UnitCosts!$B$32 | F5: =E5*Assumptions!$B$4 | G5: =B5*Assumptions!$B$63+C5*Assumptions!$B$64+D5*Assumptions!$B$65
A6: Heavy | B6: =Assumptions!B59 | C6: =Assumptions!C59 | D6: =Assumptions!D59 | E6: =B6*UnitCosts!$B$18+C6*UnitCosts!$B$22+D6*UnitCosts!$B$28+Assumptions!$B$42*UnitCosts!$B$32 | F6: =E6*Assumptions!$B$4 | G6: =B6*Assumptions!$B$63+C6*Assumptions!$B$64+D6*Assumptions!$B$65
A7: Manager seat (5x Typical) | B7: =Assumptions!B60 | C7: =Assumptions!C60 | D7: =Assumptions!D60 | E7: =B7*UnitCosts!$B$18+C7*UnitCosts!$B$22+D7*UnitCosts!$B$28+Assumptions!$B$42*UnitCosts!$B$32 | F7: =E7*Assumptions!$B$4 | G7: =B7*Assumptions!$B$63+C7*Assumptions!$B$64+D7*Assumptions!$B$65
A9: Cap check — current per-creator monthly cap (Assumptions!B49, USD 0.75)
A10: Persona | B10: Monthly $ cost | C10: % of current cap ($0.75) | D10: % of raised cap ($2.00, sensitivity)
A11: Light | B11: =E4 | C11: =E4/Assumptions!$B$49 | D11: =E4/Assumptions!$B$50
A12: Typical | B12: =E5 | C12: =E5/Assumptions!$B$49 | D12: =E5/Assumptions!$B$50
A13: Heavy | B13: =E6 | C13: =E6/Assumptions!$B$49 | D13: =E6/Assumptions!$B$50
A14: Manager seat (5x Typical) | B14: =E7 | C14: =E7/Assumptions!$B$49 | D14: =E7/Assumptions!$B$50
A15: Note: the cap is enforced per-creator. A Manager seat represents 5 creator accounts, each carrying its own USD 0.75 cap (a USD 3.75 pool in aggregate) — the % columns above compare the seat's TOTAL usage to a SINGLE creator's cap purely as a stress-test ruler, not a real gate a manager seat would hit.

Sheet OptionA
A1: Option A — Included in the 15% Platform Fee
A3: Platform fee revenue at N deals/month (deal size = Assumptions!B46, fee % = Assumptions!B45)
A4: Deals/month | B4: Fee revenue INR
A5: 1 | B5: =1*Assumptions!$B$46*Assumptions!$B$45
A6: 2 | B6: =2*Assumptions!$B$46*Assumptions!$B$45
A7: 4 | B7: =4*Assumptions!$B$46*Assumptions!$B$45
A9: AI cost as a percent of platform fee revenue, by persona and deal count
A10: Persona | B10: Deals/mo | C10: Fee revenue INR | D10: AI cost INR | E10: AI cost as % of fee | F10: Gross margin INR | G10: Gross margin %
A11: Light | B11: 1 | C11: =B5 | D11: =Personas!$F$4 | E11: =D11/C11 | F11: =C11-D11 | G11: =F11/C11
A12: Light | B12: 2 | C12: =B6 | D12: =Personas!$F$4 | E12: =D12/C12 | F12: =C12-D12 | G12: =F12/C12
A13: Light | B13: 4 | C13: =B7 | D13: =Personas!$F$4 | E13: =D13/C13 | F13: =C13-D13 | G13: =F13/C13
A14: Typical | B14: 1 | C14: =B5 | D14: =Personas!$F$5 | E14: =D14/C14 | F14: =C14-D14 | G14: =F14/C14
A15: Typical | B15: 2 | C15: =B6 | D15: =Personas!$F$5 | E15: =D15/C15 | F15: =C15-D15 | G15: =F15/C15
A16: Typical | B16: 4 | C16: =B7 | D16: =Personas!$F$5 | E16: =D16/C16 | F16: =C16-D16 | G16: =F16/C16
A17: Heavy | B17: 1 | C17: =B5 | D17: =Personas!$F$6 | E17: =D17/C17 | F17: =C17-D17 | G17: =F17/C17
A18: Heavy | B18: 2 | C18: =B6 | D18: =Personas!$F$6 | E18: =D18/C18 | F18: =C18-D18 | G18: =F18/C18
A19: Heavy | B19: 4 | C19: =B7 | D19: =Personas!$F$6 | E19: =D19/C19 | F19: =C19-D19 | G19: =F19/C19
A21: Reading this table: at 1 deal/month, AI cost eats the largest share of the fee; at 4 deals/month it is nearly noise. A Light creator on Option A is essentially free to serve at any deal cadence; a Heavy creator at only 1 deal/month gives up a visible slice of that single fee to AI cost.

Sheet OptionB
A1: Option B — Creator Subscription with AI Credits
A3: Credits needed per persona (1 turn = 1 credit, 1 brief = 3 credits, 1 voice = 2 credits, digest free)
A4: Persona | B4: Credits/month needed
A5: Light | B5: =Personas!G4
A6: Typical | B6: =Personas!G5
A7: Heavy | B7: =Personas!G6
A9: Blended cost per credit (Typical usage mix — turns + briefs + voice only; digest excluded, it is free/not a credit line)
A10: Typical persona AI cost $ (turns+briefs+voice only) | B10: =Assumptions!B58*UnitCosts!$B$18+Assumptions!C58*UnitCosts!$B$22+Assumptions!D58*UnitCosts!$B$28
A11: Typical credits (excl. digest — digest is already 0 credits) | B11: =B5
A12: Blended cost per credit, $ | B12: =B10/B11
A13: Blended cost per credit, INR | B13: =B12*Assumptions!$B$4
A15: Caution: this blended rate hides a wide spread by credit TYPE — a turn credit costs about 6-7x a brief credit, and a voice credit costs about 7x a turn credit (see UnitCosts). A flat credit price under-charges voice-heavy creators and over-charges brief-only ones. Fine for a v1 sheet; revisit if voice usage concentrates in a few accounts.
A17: Subscription tiers
A18: Tier | B18: Price INR/mo | C18: Included credits | D18: Cost to serve INR (blended) | E18: Gross margin INR | F18: Gross margin %
A19: =Assumptions!A70 | B19: =Assumptions!B70 | C19: =Assumptions!C70 | D19: =C19*$B$13 | E19: =B19-D19 | F19: =E19/B19
A20: =Assumptions!A71 | B20: =Assumptions!B71 | C20: =Assumptions!C71 | D20: =C20*$B$13 | E20: =B20-D20 | F20: =E20/B20
A21: =Assumptions!A72 | B21: =Assumptions!B72 | C21: =Assumptions!C72 | D21: =C21*$B$13 | E21: =B21-D21 | F21: =E21/B21
A23: Headroom: included credits vs. persona need
A24: Persona | B24: Credits needed | C24: Matched tier | D24: Tier included credits | E24: Headroom (credits)
A25: Light | B25: =B5 | C25: Starter | D25: =C19 | E25: =D25-B25
A26: Typical | B26: =B6 | C26: Pro | D26: =C20 | E26: =D26-B26
A27: Heavy | B27: =B7 | C27: Max | D27: =C21 | E27: =D27-B27
A29: Top-up pack economics
A30: Pack size (credits) | B30: =Assumptions!B74
A31: Pack price (INR) | B31: =Assumptions!B75
A32: Cost to serve pack, INR (blended) | B32: =B30*$B$13
A33: Margin, INR | B33: =B31-B32
A34: Margin, % | B34: =B33/B31

Sheet OptionC
A1: Option C — Hybrid: Included Baseline + Paid Top-ups + Manager Seat
A3: Included FREE credits / creator / month | B3: =Assumptions!B78
A4: Cost to serve included credits, INR (blended rate from OptionB!B13) | B4: =B3*OptionB!$B$13
A5: Cost to serve included credits, USD | B5: =B4/Assumptions!$B$4
A7: Credits beyond the free tier, by persona, and top-up cost
A8: Persona | B8: Credits needed | C8: Free credits | D8: Credits to purchase | E8: Top-up cost INR
A9: Light | B9: =OptionB!B5 | C9: =$B$3 | D9: =MAX(0,B9-C9) | E9: =D9*(Assumptions!$B$75/Assumptions!$B$74)
A10: Typical | B10: =OptionB!B6 | C10: =$B$3 | D10: =MAX(0,B10-C10) | E10: =D10*(Assumptions!$B$75/Assumptions!$B$74)
A11: Heavy | B11: =OptionB!B7 | C11: =$B$3 | D11: =MAX(0,B11-C11) | E11: =D11*(Assumptions!$B$75/Assumptions!$B$74)
A13: Manager seat (up to 5 creators)
A14: Manager seat price, INR/month | B14: =Assumptions!B79
A15: Cost to serve 5 Typical creators, full usage, INR | B15: =Personas!F7
A16: Margin, INR | B16: =B14-B15
A17: Margin, % | B17: =B16/B14
A19: Net monthly AI-credit economics per creator (absorbed free cost vs. top-up margin; excludes platform fee revenue)
A20: Persona | B20: Absorbed cost INR (free credits used) | C20: Top-up revenue INR | D20: Top-up cost INR | E20: Net INR (revenue - all cost)
A21: Light | B21: =MIN(B9,C9)*OptionB!$B$13 | C21: =E9 | D21: =D9*OptionB!$B$13 | E21: =C21-B21-D21
A22: Typical | B22: =MIN(B10,C10)*OptionB!$B$13 | C22: =E10 | D22: =D10*OptionB!$B$13 | E22: =C22-B22-D22
A23: Heavy | B23: =MIN(B11,C11)*OptionB!$B$13 | C23: =E11 | D23: =D11*OptionB!$B$13 | E23: =C23-B23-D23
A25: Light creators cost Sage the full absorbed amount with zero offsetting revenue (their usage never crosses the free 40 credits). Typical and Heavy creators cross into paid top-ups, which carry their own healthy margin (see OptionB top-up economics) and more than offset the absorbed baseline cost for that creator.

Sheet Sensitivity
A1: Break-even and Sensitivity
A3: Scenario 1 — cache hit rate drops to 30% (baseline 70%)
A4: Reduced cache hit rate | B4: =Assumptions!B82
A5: Blended cache rate $/token (reduced) | B5: =B4*UnitCosts!$D$5+(1-B4)*UnitCosts!$E$5
A6: Cacheable-tokens cost $ (reduced) | B6: =UnitCosts!$B$9*B5
A7: Base turn cost $ (reduced) | B7: =B6+UnitCosts!$B$13+UnitCosts!$B$14
A8: Cost per turn $ (reduced, incl. expected tool cost) | B8: =B7+UnitCosts!$B$17
A9: Cost per turn, INR (reduced) | B9: =B8*Assumptions!$B$4
A10: Increase vs. baseline cost/turn | B10: =B8/UnitCosts!$B$18-1
A12: Typical persona monthly cost under reduced cache hit rate
A13: $ | B13: =Assumptions!B58*B8+Assumptions!C58*UnitCosts!$B$22+Assumptions!D58*UnitCosts!$B$28+Assumptions!$B$42*UnitCosts!$B$32
A14: INR | B14: =B13*Assumptions!$B$4
A15: % of current cap ($0.75) | B15: =B13/Assumptions!$B$49
A17: Heavy persona monthly cost under reduced cache hit rate
A18: $ | B18: =Assumptions!B59*B8+Assumptions!C59*UnitCosts!$B$22+Assumptions!D59*UnitCosts!$B$28+Assumptions!$B$42*UnitCosts!$B$32
A19: INR | B19: =B18*Assumptions!$B$4
A20: % of current cap ($0.75) | B20: =B18/Assumptions!$B$49
A21: % of raised cap ($2.00) | B21: =B18/Assumptions!$B$50
A23: Scenario 2 — Sonnet used for brief extraction instead of Haiku
A24: Cost per extraction $ (Sonnet) | B24: =Assumptions!B32*UnitCosts!$B$5+Assumptions!B33*UnitCosts!$C$5
A25: Cost per extraction, INR (Sonnet) | B25: =B24*Assumptions!$B$4
A26: Multiple of Haiku baseline cost | B26: =B24/UnitCosts!$B$22
A28: Typical persona monthly cost with Sonnet extraction
A29: $ | B29: =Assumptions!B58*UnitCosts!$B$18+Assumptions!C58*B24+Assumptions!D58*UnitCosts!$B$28+Assumptions!$B$42*UnitCosts!$B$32
A30: INR | B30: =B29*Assumptions!$B$4
A31: % of current cap ($0.75) | B31: =B29/Assumptions!$B$49
A33: Heavy persona monthly cost with Sonnet extraction
A34: $ | B34: =Assumptions!B59*UnitCosts!$B$18+Assumptions!C59*B24+Assumptions!D59*UnitCosts!$B$28+Assumptions!$B$42*UnitCosts!$B$32
A35: INR | B35: =B34*Assumptions!$B$4
A36: % of current cap ($0.75) | B36: =B34/Assumptions!$B$49
A38: Scenario 3 — per-creator cap raised from $0.75 to $2.00
A39: Typical persona baseline monthly $ / raised cap | B39: =Personas!E5/Assumptions!$B$50
A40: Heavy persona baseline monthly $ / raised cap | B40: =Personas!E6/Assumptions!$B$50
A42: Combined worst case — Heavy persona, 30% cache hit AND Sonnet extraction
A43: $ | B43: =Assumptions!B59*B8+Assumptions!D59*UnitCosts!$B$28+Assumptions!C59*B24+Assumptions!$B$42*UnitCosts!$B$32
A44: INR | B44: =B43*Assumptions!$B$4
A45: % of current cap ($0.75) | B45: =B43/Assumptions!$B$49
A46: % of raised cap ($2.00) | B46: =B43/Assumptions!$B$50
A48: Reading this sheet: degraded caching alone pushes a Typical creator over the current $0.75 cap and a Heavy creator to roughly 3x it. Switching brief extraction to Sonnet triples that one line item on its own. Combined (worst case), a Heavy creator would exceed even a cap RAISED to $2.00 — the cap, not just the price sheet, needs a second look if usage skews heavy or caching underperforms in production.
A50: GST note (18% on a subscription charged to an Indian creator)
...
